Workbook

Sheet Tableau de bord
B2: Analyse des ventes mensuelles des clients affiliés
C6: SEPT | D6: OCT | E6: NOV | F6: DEC | G6: JAN | H6: FEV | J6: TOTAL
B8: bien de conso. | C8: 10543 | D8: 11458 | E8: 13520 | F8: 14023 | G8: 14983 | H8: =SUMIF('DATA Février (clients affiliés)'!D1:D700,"bien de conso.",'DATA Février (clients affiliés)'!C1:C700) -> 14763.9 | J8: =SUM(C8:H8) -> 79290.9
B9: nourriture | C9: 13855 | D9: 16052 | E9: 16797 | F9: 17582 | G9: 18216 | H9: =SUMIF('DATA Février (clients affiliés)'!D1:D700,"nourriture",'DATA Février (clients affiliés)'!C1:C700) -> 24898.82 | J9: =SUM(C9:H9) -> 107400.82
B10: high tech | C10: 3002 | D10: 3769 | E10: 4230 | F10: 4341 | G10: 2713 | H10: =SUMIF('DATA Février (clients affiliés)'!D1:D700,"high tech",'DATA Février (clients affiliés)'!C1:C700) -> 0 | J10: =SUM(C10:H10) -> 18055
B11: TOTAL | C11: 27400 | D11: 31279 | E11: 34547 | F11: 35946 | G11: 35912 | H11: =SUM(H8:H10) -> 39662.72 | J11: =SUM(C11:H11) -> 204746.72
B14: TEMPS D'ACHAT | C14: NB TRANSACTIONS | D14: CA TOTAL
B15: Inférieur à 4 min. | C15: =COUNTIF('DATA Février (clients affiliés)'!B2:B661,"<4") -> 47 | D15: =SUMIF('DATA Février (clients affiliés)'!B2:B661,"<4",'DATA Février (clients affiliés)'!C2:C661) -> 1562.73
B16: Supérieur à 9 min 30 | C16: =COUNTIF('DATA Février (clients affiliés)'!B2:B662,">9,5") -> 91 | D16: =SUMIF('DATA Février (clients affiliés)'!B3:B662,">9,5",'DATA Février (clients affiliés)'!C3:C662) -> 7577.32
B20: Graphique montrant l'évolution du chiffre d'affaires au sein de chaque catégorie (de septembre à février)
B45: Graphique représentant le chiffre d'affaires total pour chaque catégorie (de septembre à février)
B70: Top 10 des clients avec le détail par catégorie (Pour le mois de février)
B95: Graphique représentant le montant du panier en fonction du temps passé sur le site pour les clients affiliés (Pour le mois de Février)
B120: Graphique représentant le chiffre d'affaires par catégorie en pourcentage (pour le mois de février)

Sheet Tableau Client x Catégorie
B1: Column Labels
B2: bien de conso. | D2: nourriture | F2: Total Nombre d'achats | G2: Total Chiffre d'affaires
A3: ID Client | B3: Nombre d'achats | C3: Chiffre d'affaires | D3: Nombre d'achats | E3: Chiffre d'affaires
A4: 24 | B4: 10 | C4: 631.71 | D4: 14 | E4: 878.62 | F4: 24 | G4: 1510.33
A5: 25 | B5: 5 | C5: 368.74 | D5: 18 | E5: 1028.41 | F5: 23 | G5: 1397.15
A6: 26 | B6: 10 | C6: 619.51 | D6: 11 | E6: 719.24 | F6: 21 | G6: 1338.75
A7: 36 | B7: 8 | C7: 505.64 | D7: 11 | E7: 729.21 | F7: 19 | G7: 1234.85
A8: 20 | B8: 6 | C8: 368.8 | D8: 12 | E8: 779.15 | F8: 18 | G8: 1147.95
A9: 35 | B9: 7 | C9: 482.34 | D9: 9 | E9: 639.66 | F9: 16 | G9: 1122
A10: 31 | B10: 11 | C10: 589.96 | D10: 8 | E10: 525.25 | F10: 19 | G10: 1115.21
A11: 38 | B11: 10 | C11: 568.76 | D11: 9 | E11: 526.25 | F11: 19 | G11: 1095.01
A12: 15 | B12: 3 | C12: 190.66 | D12: 13 | E12: 872.34 | F12: 16 | G12: 1063
A13: 22 | B13: 5 | C13: 291.37 | D13: 10 | E13: 743.33 | F13: 15 | G13: 1034.7
A14: 28 | B14: 9 | C14: 544.32 | D14: 8 | E14: 481.02 | F14: 17 | G14: 1025.34
A15: 18 | B15: 8 | C15: 531.19 | D15: 7 | E15: 483.06 | F15: 15 | G15: 1014.25
... A29: 5 | B29: 3 | C29: 163.14 | D29: 10 | E29: 580.52 | F29: 13 | G29: 743.66
A30: 32 | D30: 11 | E30: 742.91 | F30: 11 | G30: 742.91
A31: 19 | B31: 3 | C31: 169.84 | D31: 11 | E31: 531.19 | F31: 14 | G31: 701.03
A32: 3 | B32: 5 | C32: 360.62 | D32: 4 | E32: 275.13 | F32: 9 | G32: 635.75
A33: 42 | B33: 3 | C33: 211.31 | D33: 7 | E33: 411.21 | F33: 10 | G33: 622.52
A34: 13 | B34: 4 | C34: 284.57 | D34: 7 | E34: 311.83 | F34: 11 | G34: 596.4
A35: 6 | B35: 6 | C35: 338.63 | D35: 4 | E35: 248.14 | F35: 10 | G35: 586.77
A36: 21 | D36: 10 | E36: 573.63 | F36: 10 | G36: 573.63
A37: 33 | B37: 4 | C37: 246.23 | D37: 4 | E37: 304.17 | F37: 8 | G37: 550.4
A38: 39 | B38: 4 | C38: 231.14 | D38: 5 | E38: 311.79 | F38: 9 | G38: 542.93
A39: 46 | B39: 2 | C39: 142.08 | D39: 5 | E39: 386.6 | F39: 7 | G39: 528.68
A40: 40 | B40: 2 | C40: 88.13 | D40: 6 | E40: 433.92 | F40: 8 | G40: 522.05
A41: 51 | B41: 2 | C41: 119.58 | D41: 6 | E41: 392.12 | F41: 8 | G41: 511.7
A42: 8 | B42: 2 | C42: 136.15 | D42: 7 | E42: 373.76 | F42: 9 | G42: 509.91
A43: 48 | B43: 2 | C43: 142.59 | D43: 7 | E43: 352.4 | F43: 9 | G43: 494.99
A44: 43 | B44: 5 | C44: 259.49 | D44: 5 | E44: 229.98 | F44: 10 | G44: 489.47
A45: 44 | B45: 2 | C45: 173.57 | D45: 4 | E45: 293.58 | F45: 6 | G45: 467.15
A46: 37 | B46: 2 | C46: 112.71 | D46: 6 | E46: 338.86 | F46: 8 | G46: 451.57
A47: 12 | B47: 3 | C47: 182.85 | D47: 5 | E47: 260.83 | F47: 8 | G47: 443.68
A48: 1 | B48: 4 | C48: 201.41 | D48: 5 | E48: 233.41 | F48: 9 | G48: 434.82
... A51: 49 | B51: 1 | C51: 59.39 | D51: 4 | E51: 207.24 | F51: 5 | G51: 266.63
A52: 50 | D52: 5 | E52: 254.44 | F52: 5 | G52: 254.44
A53: 45 | B53: 2 | C53: 118.16 | D53: 2 | E53: 132.71 | F53: 4 | G53: 250.87
A54: 11 | B54: 3 | C54: 150.74 | D54: 2 | E54: 99.86 | F54: 5 | G54: 250.6
A55: 57 | D55: 4 | E55: 196.31 | F55: 4 | G55: 196.31
...

Sheet DATA Février (clients affiliés)
A1: ID client | B1: Temps d'achat | C1: Montant | D1: Categorie
A2: 16 | B2: 5.22 | C2: 48.26 | D2: bien de conso. | E2: =IF(D2="bien de conso.",1,0) -> 1 | F2: =IF($D2="nourriture",1,0) -> 0 | G2: =IF($D2="high tech",1,0) -> 0
A3: 52 | B3: 6.17 | C3: 55.46 | D3: bien de conso. | E3: =IF(D3="bien de conso.",1,0) -> 1 | F3: =IF($D3="nourriture",1,0) -> 0 | G3: =IF($D3="high tech",1,0) -> 0
A4: 58 | B4: 5.36 | C4: 53.2 | D4: bien de conso. | E4: =IF(D4="bien de conso.",1,0) -> 1 | F4: =IF($D4="nourriture",1,0) -> 0 | G4: =IF($D4="high tech",1,0) -> 0
A5: 11 | B5: 5.46 | C5: 47.61 | D5: bien de conso. | E5: =IF(D5="bien de conso.",1,0) -> 1 | F5: =IF($D5="nourriture",1,0) -> 0 | G5: =IF($D5="high tech",1,0) -> 0
A6: 25 | B6: 9.77 | C6: 81.57 | D6: bien de conso. | E6: =IF(D6="bien de conso.",1,0) -> 1 | F6: =IF($D6="nourriture",1,0) -> 0 | G6: =IF($D6="high tech",1,0) -> 0
A7: 40 | B7: 6.96 | C7: 63.5 | D7: bien de conso. | E7: =IF(D7="bien de conso.",1,0) -> 1 | F7: =IF($D7="nourriture",1,0) -> 0 | G7: =IF($D7="high tech",1,0) -> 0
A8: 8 | B8: 5.64 | C8: 46.17 | D8: bien de conso. | E8: =IF(D8="bien de conso.",1,0) -> 1 | F8: =IF($D8="nourriture",1,0) -> 0 | G8: =IF($D8="high tech",1,0) -> 0
A9: 1 | B9: 4.56 | C9: 46.9 | D9: bien de conso. | E9: =IF(D9="bien de conso.",1,0) -> 1 | F9: =IF($D9="nourriture",1,0) -> 0 | G9: =IF($D9="high tech",1,0) -> 0
A10: 36 | B10: 5.2 | C10: 39.99 | D10: bien de conso. | E10: =IF(D10="bien de conso.",1,0) -> 1 | F10: =IF($D10="nourriture",1,0) -> 0 | G10: =IF($D10="high tech",1,0) -> 0
A11: 14 | B11: 6.28 | C11: 58.85 | D11: bien de conso. | E11: =IF(D11="bien de conso.",1,0) -> 1 | F11: =IF($D11="nourriture",1,0) -> 0 | G11: =IF($D11="high tech",1,0) -> 0
A12: 17 | B12: 6.06 | C12: 55.41 | D12: bien de conso. | E12: =IF(D12="bien de conso.",1,0) -> 1 | F12: =IF($D12="nourriture",1,0) -> 0 | G12: =IF($D12="high tech",1,0) -> 0
A13: 19 | B13: 6.57 | C13: 64.61 | D13: bien de conso. | E13: =IF(D13="bien de conso.",1,0) -> 1 | F13: =IF($D13="nourriture",1,0) -> 0 | G13: =IF($D13="high tech",1,0) -> 0
... A661: 2 | B661: 12.4 | C661: 90.66 | D661: nourriture | E661: =IF(D661="bien de conso.",1,0) -> 0 | F661: =IF($D661="nourriture",1,0) -> 1 | G661: =IF($D661="high tech",1,0) -> 0
